{"trial_id": "06", "hyperparameters": {"space": [{"class_name": "Int", "config": {"name": "conv_1_filter", "default": null, "conditions": [], "min_value": 32, "max_value": 128, "step": 16, "sampling": "linear"}}, {"class_name": "Int", "config": {"name": "conv_1_kernel", "default": null, "conditions": [], "min_value": 3, "max_value": 5, "step": 1, "sampling": "linear"}}, {"class_name": "Int", "config": {"name": "conv_2_filter", "default": null, "conditions": [], "min_value": 32, "max_value": 128, "step": 16, "sampling": "linear"}}, {"class_name": "Int", "config": {"name": "conv_2_kernel", "default": null, "conditions": [], "min_value": 3, "max_value": 5, "step": 1, "sampling": "linear"}}, {"class_name": "Int", "config": {"name": "lstm_1_units", "default": null, "conditions": [], "min_value": 64, "max_value": 256, "step": 32, "sampling": "linear"}}, {"class_name": "Int", "config": {"name": "lstm_2_units", "default": null, "conditions": [], "min_value": 64, "max_value": 256, "step": 32, "sampling": "linear"}}, {"class_name": "Int", "config": {"name": "dense_units", "default": null, "conditions": [], "min_value": 64, "max_value": 256, "step": 32, "sampling": "linear"}}, {"class_name": "Float", "config": {"name": "learning_rate", "default": 0.001, "conditions": [], "min_value": 0.0001, "max_value": 0.01, "step": null, "sampling": "log"}}], "values": {"conv_1_filter": 80, "conv_1_kernel": 5, "conv_2_filter": 32, "conv_2_kernel": 5, "lstm_1_units": 128, "lstm_2_units": 96, "dense_units": 96, "learning_rate": 0.00053256878362791}}, "metrics": {"metrics": {}}, "score": null, "best_step": 0, "status": "FAILED", "message": "Traceback (most recent call last):\n  File \"C:\\Users\\my220\\anaconda3\\Lib\\site-packages\\keras_tuner\\src\\engine\\base_tuner.py\", line 274, in _try_run_and_update_trial\n    self._run_and_update_trial(trial, *fit_args, **fit_kwargs)\n  File \"C:\\Users\\my220\\anaconda3\\Lib\\site-packages\\keras_tuner\\src\\engine\\base_tuner.py\", line 239, in _run_and_update_trial\n    results = self.run_trial(trial, *fit_args, **fit_kwargs)\n              ^^^^^^^^^^^^^^^^^^^^^^^^^^^^^^^^^^^^^^^^^^^^^^\n  File \"C:\\Users\\my220\\anaconda3\\Lib\\site-packages\\keras_tuner\\src\\engine\\tuner.py\", line 314, in run_trial\n    obj_value = self._build_and_fit_model(trial, *args, **copied_kwargs)\n                ^^^^^^^^^^^^^^^^^^^^^^^^^^^^^^^^^^^^^^^^^^^^^^^^^^^^^^^^\n  File \"C:\\Users\\my220\\anaconda3\\Lib\\site-packages\\keras_tuner\\src\\engine\\tuner.py\", line 233, in _build_and_fit_model\n    results = self.hypermodel.fit(hp, model, *args, **kwargs)\n              ^^^^^^^^^^^^^^^^^^^^^^^^^^^^^^^^^^^^^^^^^^^^^^^\n  File \"C:\\Users\\my220\\anaconda3\\Lib\\site-packages\\keras_tuner\\src\\engine\\hypermodel.py\", line 149, in fit\n    return model.fit(*args, **kwargs)\n           ^^^^^^^^^^^^^^^^^^^^^^^^^^\n  File \"C:\\Users\\my220\\anaconda3\\Lib\\site-packages\\keras\\src\\utils\\traceback_utils.py\", line 122, in error_handler\n    raise e.with_traceback(filtered_tb) from None\n  File \"C:\\Users\\my220\\anaconda3\\Lib\\site-packages\\keras\\src\\utils\\traceback_utils.py\", line 124, in error_handler\n    del filtered_tb\nValueError: Exception encountered when calling Conv1D.call().\n\n\u001b[1mNegative dimension size caused by subtracting 5 from 4 for '{{node sequential_1/conv1d_1_2/convolution}} = Conv2D[T=DT_FLOAT, data_format=\"NHWC\", dilations=[1, 1, 1, 1], explicit_paddings=[], padding=\"VALID\", strides=[1, 1, 1, 1], use_cudnn_on_gpu=true](sequential_1/conv1d_1_2/convolution/ExpandDims, sequential_1/conv1d_1_2/convolution/ExpandDims_1)' with input shapes: [?,1,4,80], [1,5,80,32].\u001b[0m\n\nArguments received by Conv1D.call():\n  \u2022 inputs=tf.Tensor(shape=(None, 4, 80), dtype=float32)\n"}